Workbook

Sheet Overall analysis
B2: Platform System information
B3: Item | C3: Data. | E3: Result | F3: Note
B4: 1.Check Board
B5: Mode configuration | C5: ='CPLD1 reg'!AO18 -> 00 | E5: =IF(C5="00","2S",IF(C5="01","8S",IF(C5="10","!!!D2ScheckFRU!!!",IF(C5="11","4S","ERR")))) -> 2S
B6: Node ID | C6: ='CPLD1 reg'!AO17 -> 11 | E6: =IF(C6="00","SLED0",IF(C6="01","SLED1",IF(C6="10","SLED2",IF(C6="11","SLED3","ERR")))) -> SLED3
B7: HPM REVISION ID | C7: ='CPLD1 reg'!AO14 -> 110 | E7: =IF(C7="000","POC",IF(C7="100","EVT",IF(C7="010","DVT",IF(C7="110","PVT",IF(C7="001","MP",""))))) -> PVT
B8: SCM REVISION ID | C8: ='SCM reg'!AO22 -> 011 | E8: =IF(C8="000","POC",IF(C8="100","EVT",IF(C8="010","DVT",IF(C8="110","PVT",IF(C8="001","MP","")))))
B9: CPU0 Presnt | C9: ='CPLD1 reg'!AO8 -> 0 | E9: =IF(C9="0","CPU0 Install", "No CPU") -> CPU0 Install
B10: CPU1 Presnt | C10: ='CPLD1 reg'!AO12 -> 0 | E10: =IF(C10="0","CPU1 Install", "No CPU") -> CPU1 Install
B11: 2.Check version
B12: GLB CPLD | C12: ='GLB reg'!AY53 -> 02 | D12: ='GLB reg'!AY54 -> 0a | E12: =_xlfn.TEXTJOIN(".",TRUE,C12:D12) -> 02.0a
B13: SCM CPLD | C13: =0&'SCM reg'!AO5 -> 03 | D13: =0&'SCM reg'!AO6 -> 06 | E13: =_xlfn.TEXTJOIN(".",TRUE,C13:D13) -> 03.06
B14: CPLD1 | C14: ='CPLD1 reg'!P17 -> 02 | D14: ='CPLD1 reg'!Q17 -> 0a | E14: =_xlfn.TEXTJOIN(".",TRUE,C14:D14) -> 02.0a
B15: CPLD2 | C15: ='CPLD2 reg'!AQ48 -> 02 | D15: ='CPLD2 reg'!AQ49 -> 08 | E15: =_xlfn.TEXTJOIN(".",TRUE,C15:D15) -> 02.08
B18: Analysis
B19: 3.Check SCM SGPIO link
B20: Item | C20: EXP. | D20: Data. | E20: Result | F20: Note
B21: SGPIO 1 Link Status | C21: ='SCM reg'!AN10 -> 11 | D21: ='SCM reg'!AO10 -> 11 | E21: =IF(C21=D21, "Y", "N") -> Y
B22: SGPIO 0 Link Status | C22: ='SCM reg'!AN11 -> 11 | D22: ='SCM reg'!AO11 -> 11 | E22: =IF(C22=D22, "Y", "N") -> Y
B23: SGPIO 0 CRC error count | C23: ='SCM reg'!AN14 -> 00 | D23: ='SCM reg'!AO14 -> 00 | E23: =IF(C23=D23, "Y", "N") -> Y
B24: SGPIO 1 CRC error count | C24: ='SCM reg'!AN15 -> 00 | D24: ='SCM reg'!AO15 -> 00 | E24: =IF(C24=D24, "Y", "N") -> Y | F24: If there is any 'N', change SCM. | H24: 0xA0[3:0] | I24: System Power on status
B25: 4.Check SGPIO link (CPLD1 -PDB) | H25: =TEXT(0,"0000") -> 0000 | I25: Default
B26: SGPIO Link Status (CPLD1 - PDB) | C26: =TRIM('CPLD1 reg'!BY28) -> 1 | D26: =TRIM('CPLD1 reg'!BZ28) -> 1 | E26: =IF(ROUND(D26,2)=ROUND(C26,2),"Y","N") -> Y | H26: =TEXT(1,"0000") -> 0001 | I26: SCM AUX (HPM STBY_EN) | J26: >>> check SCM
B27: SGPIO Link CRC ERROR(CPLD1 - PDB) | C27: =TRIM('CPLD1 reg'!BY32) -> 00000000 | D27: =TRIM('CPLD1 reg'!BZ32) -> 00000000 | E27: =IF(ROUND(D27,2)=ROUND(C27,2),"Y","N") -> Y | H27: =TEXT(10,"0000") -> 0010 | I27: BMC Boot (HPM STBY_RSTn) | J27: >>> check SCM
B28: 4.Check CPLD2 SGPIO link | H28: =TEXT(11,"0000") -> 0011 | I28: CPU Aux OK (S5 state) | J28: >>> check UPI, sideband cable, CPU(Plug in to confirm)
B29: SGPIO 2 Link Status (CPLD1 - CPLD2) | C29: ='CPLD2 reg'!AP36 -> 1 | D29: ='CPLD2 reg'!AQ36 -> 1 | E29: =IF(ROUND(D29,2)=ROUND(C29,2),"Y","N") -> Y | H29: =TEXT(100,"0000") -> 0100 | I29: Enable main power | J29: >>> check MB vr, change MB
B30: ESPI Status (CPLD2-BIOS) | C30: ='CPLD2 reg'!AP37 -> 1 | D30: ='CPLD2 reg'!AQ37 -> 0 | E30: =IF(ROUND(D30,2)=ROUND(C30,2),"Y","N") -> N | H30: =TEXT(101,"0000") -> 0101 | I30: CPU MEM PWR | J30: >>> check DIMM
B31: SGPIO 2 CRC error count | C31: ='CPLD2 reg'!AP38 -> 00 | D31: ='CPLD2 reg'!AQ38 -> 00 | E31: =IF(ROUND(D31,2)=ROUND(C31,2),"Y","N") -> Y | H31: =TEXT(110,"0000") -> 0110 | I31: CPU S0 PWROK
B32: 5.Check GLB SGPIO link | H32: =TEXT(111,"0000") -> 0111 | I32: CPU PWRGD
B33: SGPIO Link Status (CPLD1 - PDB) | C33: ='GLB reg'!AX4 -> 1 | D33: ='GLB reg'!AY4 -> 1 | E33: =IF(ROUND(D33,2)=ROUND(C33,2),"Y","N") -> Y | H33: 1000 | I33: CPU RESET
B34: SGPIO CRC Error Count | C34: ='GLB reg'!AX5 -> 00 | D34: ='GLB reg'!AY5 -> 00 | E34: =IF(ROUND(D34,2)=ROUND(C34,2),"Y","N") -> Y | H34: 1010 | I34: ERROR state | J34: >>> S3M,or change CPU
B35: SGPIO CRC Good Count | C35: ='GLB reg'!AX6 -> don't care | D35: ='GLB reg'!AY6 -> d1 | E35: =IF(HEX2DEC(D35)>0,"Y","N") -> Y | H35: =TEXT(0,"1011") -> 1011 | I35: ST_ADR
B36: 5.Check SCM Power State | H36: =TEXT(0,"1100") -> 1100 | I36: ST_HANDSHAKE_0
B37: DC-SCM VR on/off status Register | C37: ='SCM reg'!AN19 -> 09 | D37: ='SCM reg'!AO19 -> 09 | E37: =IF(ROUND(D37,2)=ROUND(C37,2),"Y","N") -> Y | F37: If there is any 'N', change SCM. | H37: 1111 | I37: Platform on (S0 state)
B38: Power Good Status Register | C38: ='SCM reg'!AN20 -> 11111111 | D38: ='SCM reg'!AO20 -> 11111111 | E38: =IF(ROUND(D38,2)=ROUND(C38,2),"Y","N") -> Y | F38: If there is any 'N', change SCM.
B39: 6.Check System Power State
B40: System Power on status | C40: =TRIM('CPLD1 reg'!BY7) -> 1111 | D40: =TRIM('CPLD1 reg'!BZ7) -> 1111 | E40: =IF(D40="0000","Default", IF(D40="0001","SCM AUX (HPM STBY_EN)", IF(D40="0010","BMC Boot (HPM STBY_RSTn)", IF(D40="0011","CPU Aux OK (S5 state)", IF(D40="0100","Enable main power", IF(D40="0101","CPU MEM PWR", IF(D40="0110","CPU S0 PWROK", IF(D40="0111","CPU PWRGD", IF(D40="1000","CPU RESET", IF(D40="1001","No description", IF(D40="1010","ERROR state", IF(D40="1011","No description", IF(D40="1100","No description", IF(D40="1101","No description", IF(D40="1110","No description", IF(D40="1111","Platform on (S0 state)", "Unknown Code")))))))))))))))) -> Platform on (S0 state)
B41: 7.Check UPI Cable
B42: CPU0/1 SMB ALERT | C42: =TRIM('CPLD1 reg'!BC5) -> 00000000 | D42: =TRIM('CPLD1 reg'!BD5) -> 00000000 | E42: =IF(ROUND(D42,2)=ROUND(C42,2),"Y","N") -> Y
B43: SMB_MM7_SEL | C43: =TRIM('CPLD1 reg'!BC6) -> 0 | D43: =TRIM('CPLD1 reg'!BD6) -> 0 | E43: =IF(ROUND(D43,2)=ROUND(C43,2),"Y","N") -> Y
...

Sheet GLB reg
A1: LOG | B1: 0 | C1: 1 | D1: 2 | E1: 3 | F1: 4 | G1: 5 | H1: 6 | I1: 7 | J1: 8 | K1: 9 | L1: A | M1: B | N1: C | O1: D | P1: E | Q1: F | S1: 0 | T1: 1 | U1: 2 | V1: 3 | W1: 4 | X1: 5 | Y1: 6 | Z1: 7 | AA1: 8 | AB1: 9 | AC1: A | AD1: B | AE1: C | AF1: D | AG1: E | AH1: F
A2: 0 | B2: =MID($A22,5,2) -> 10 | C2: =MID($A22,8,2) -> 00 | D2: =MID($A22,11,2) -> 00 | E2: =MID($A22,14,2) -> 00 | F2: =MID($A22,17,2) -> ff | G2: =MID($A22,20,2) -> 33 | H2: =MID($A22,23,2) -> 0f | I2: =MID($A22,26,2) -> ff | J2: =MID($A22,29,2) -> ff | K2: =MID($A22,32,2) -> ff | L2: =MID($A22,35,2) -> ff | M2: =MID($A22,38,2) -> 00 | N2: =MID($A22,41,2) -> 00 | O2: =MID($A22,44,2) -> 00 | P2: =MID($A22,47,2) -> 00 | Q2: =MID($A22,50,2) -> 00 | S2: =TEXT(HEX2BIN(B2),"00000000") -> 00010000 | T2: =TEXT(HEX2BIN(C2),"00000000") -> 00000000 | U2: =TEXT(HEX2BIN(D2),"00000000") -> 00000000 | V2: =TEXT(HEX2BIN(E2),"00000000") -> 00000000 | W2: =TEXT(HEX2BIN(F2),"00000000") -> 11111111 | X2: =TEXT(HEX2BIN(G2),"00000000") -> 00110011 | Y2: =TEXT(HEX2BIN(H2),"00000000") -> 00001111 | Z2: =TEXT(HEX2BIN(I2),"00000000") -> 11111111 | ... AH2: =TEXT(HEX2BIN(Q2),"00000000") -> 00000000
A3: 10 | B3: =MID($A23,5,2) -> 00 | C3: =MID($A23,8,2) -> 00 | D3: =MID($A23,11,2) -> 00 | E3: =MID($A23,14,2) -> 00 | F3: =MID($A23,17,2) -> 00 | G3: =MID($A23,20,2) -> 00 | H3: =MID($A23,23,2) -> 00 | I3: =MID($A23,26,2) -> 00 | J3: =MID($A23,29,2) -> 00 | K3: =MID($A23,32,2) -> 64 | L3: =MID($A23,35,2) -> 06 | M3: =MID($A23,38,2) -> 1e | N3: =MID($A23,41,2) -> 00 | O3: =MID($A23,44,2) -> 0f | P3: =MID($A23,47,2) -> 02 | Q3: =MID($A23,50,2) -> 00 | S3: =TEXT(HEX2BIN(B3),"00000000") -> 00000000 | T3: =TEXT(HEX2BIN(C3),"00000000") -> 00000000 | U3: =TEXT(HEX2BIN(D3),"00000000") -> 00000000 | V3: =TEXT(HEX2BIN(E3),"00000000") -> 00000000 | W3: =TEXT(HEX2BIN(F3),"00000000") -> 00000000 | X3: =TEXT(HEX2BIN(G3),"00000000") -> 00000000 | Y3: =TEXT(HEX2BIN(H3),"00000000") -> 00000000 | Z3: =TEXT(HEX2BIN(I3),"00000000") -> 00000000 | ... AH3: =TEXT(HEX2BIN(Q3),"00000000") -> 00000000 | AM3: Common info | AW3: SGPIO Link
A4: 20 | B4: =MID($A24,5,2) -> 00 | C4: =MID($A24,8,2) -> 00 | D4: =MID($A24,11,2) -> 00 | E4: =MID($A24,14,2) -> 00 | F4: =MID($A24,17,2) -> 00 | G4: =MID($A24,20,2) -> 00 | H4: =MID($A24,23,2) -> 00 | I4: =MID($A24,26,2) -> 00 | J4: =MID($A24,29,2) -> 00 | K4: =MID($A24,32,2) -> 00 | L4: =MID($A24,35,2) -> 00 | M4: =MID($A24,38,2) -> 00 | N4: =MID($A24,41,2) -> 00 | O4: =MID($A24,44,2) -> 00 | P4: =MID($A24,47,2) -> 00 | Q4: =MID($A24,50,2) -> 00 | S4: =TEXT(HEX2BIN(B4),"00000000") -> 00000000 | T4: =TEXT(HEX2BIN(C4),"00000000") -> 00000000 | U4: =TEXT(HEX2BIN(D4),"00000000") -> 00000000 | V4: =TEXT(HEX2BIN(E4),"00000000") -> 00000000 | W4: =TEXT(HEX2BIN(F4),"00000000") -> 00000000 | X4: =TEXT(HEX2BIN(G4),"00000000") -> 00000000 | Y4: =TEXT(HEX2BIN(H4),"00000000") -> 00000000 | Z4: =TEXT(HEX2BIN(I4),"00000000") -> 00000000 | ... AH4: =TEXT(HEX2BIN(Q4),"00000000") -> 00000000 | AM4: CPU/Board ID | AN4: EXP. | AO4: Data. | AP4: Analyze | AS4: 0x00[7:4] | AT4: Wirte Busy Flag | AV4: 0xA6 [0] | AW4: SGPIO Link Status (CPLD1 - PDB) | AX4: 1 | AY4: =MID($Y12,8,1) -> 1 | AZ4: =IF(BIN2DEC(AY4)>0,"link stable","!!!!link ERROR!!!") -> link stable
A5: 30 | B5: =MID($A25,5,2) -> 00 | C5: =MID($A25,8,2) -> 00 | D5: =MID($A25,11,2) -> 00 | E5: =MID($A25,14,2) -> 00 | F5: =MID($A25,17,2) -> 2d | G5: =MID($A25,20,2) -> 90 | H5: =MID($A25,23,2) -> 00 | I5: =MID($A25,26,2) -> 00 | J5: =MID($A25,29,2) -> 00 | K5: =MID($A25,32,2) -> 00 | L5: =MID($A25,35,2) -> f0 | M5: =MID($A25,38,2) -> 00 | N5: =MID($A25,41,2) -> 00 | O5: =MID($A25,44,2) -> 00 | P5: =MID($A25,47,2) -> 00 | Q5: =MID($A25,50,2) -> 00 | S5: =TEXT(HEX2BIN(B5),"00000000") -> 00000000 | T5: =TEXT(HEX2BIN(C5),"00000000") -> 00000000 | U5: =TEXT(HEX2BIN(D5),"00000000") -> 00000000 | V5: =TEXT(HEX2BIN(E5),"00000000") -> 00000000 | W5: =TEXT(HEX2BIN(F5),"00000000") -> 00101101 | X5: =TEXT(HEX2BIN(G5),"00000000") -> 10010000 | Y5: =TEXT(HEX2BIN(H5),"00000000") -> 00000000 | Z5: =TEXT(HEX2BIN(I5),"00000000") -> 00000000 | ... AH5: =TEXT(HEX2BIN(Q5),"00000000") -> 00000000 | AL5: 0x00 [7:4] | AM5: Write Busy Flag | AN5: 0001 | AO5: =MID($S2,1,4) -> 0001 | AP5: =IF(AO5="0001", "SLED0 USE", IF(AO5="0010", "SLED1 USE", IF(AO5="0100", "SLED2 USE", IF(AO5="1000", "SLED3 USE", "undefine")))) -> SLED0 USE | AS5: 4'b0001 | AT5: SLED0 USE | AV5: 0xA7 [7:0] | AW5: SGPIO CRC Error Count | AX5: 00 | AY5: =MID($I12,1,8) -> 00 | AZ5: =IF(BIN2DEC(AY5)>0,"!!!!CRC ERROR!!!","link stable") -> link stable
A6: 40 | B6: =MID($A26,5,2) -> 10 | C6: =MID($A26,8,2) -> 00 | D6: =MID($A26,11,2) -> 00 | E6: =MID($A26,14,2) -> 00 | F6: =MID($A26,17,2) -> 00 | G6: =MID($A26,20,2) -> 00 | H6: =MID($A26,23,2) -> 00 | I6: =MID($A26,26,2) -> 00 | J6: =MID($A26,29,2) -> 00 | K6: =MID($A26,32,2) -> 00 | L6: =MID($A26,35,2) -> 00 | M6: =MID($A26,38,2) -> 00 | N6: =MID($A26,41,2) -> 00 | O6: =MID($A26,44,2) -> 00 | P6: =MID($A26,47,2) -> 00 | Q6: =MID($A26,50,2) -> 00 | S6: =TEXT(HEX2BIN(B6),"00000000") -> 00010000 | T6: =TEXT(HEX2BIN(C6),"00000000") -> 00000000 | U6: =TEXT(HEX2BIN(D6),"00000000") -> 00000000 | V6: =TEXT(HEX2BIN(E6),"00000000") -> 00000000 | W6: =TEXT(HEX2BIN(F6),"00000000") -> 00000000 | X6: =TEXT(HEX2BIN(G6),"00000000") -> 00000000 | Y6: =TEXT(HEX2BIN(H6),"00000000") -> 00000000 | Z6: =TEXT(HEX2BIN(I6),"00000000") -> 00000000 | ... AH6: =TEXT(HEX2BIN(Q6),"00000000") -> 00000000 | AL6: 0x00 [0] | AM6: FM_MISC_IOB_4S_N_8S_MODE | AN6: 0 | AO6: =MID($S2,8,1) -> 0 | AP6: =IF(AO6="0", "2S/4S", IF(AO6="1", "8S", "error")) -> 2S/4S | AS6: 4'b0010 | AT6: SLED1 USE | AV6: 0xA8 [7:0] | AW6: SGPIO CRC Good Count | AX6: don't care | AY6: =MID($J12,1,8) -> d1 | AZ6: =IF(HEX2DEC(AY6)>0,"link stable","!!!!check CRC!!!") -> link stable
A7: 50 | B7: =MID($A27,5,2) -> 10 | C7: =MID($A27,8,2) -> 04 | D7: =MID($A27,11,2) -> 02 | E7: =MID($A27,14,2) -> 0d | F7: =MID($A27,17,2) -> 01 | G7: =MID($A27,20,2) -> 00 | H7: =MID($A27,23,2) -> 00 | I7: =MID($A27,26,2) -> 00 | J7: =MID($A27,29,2) -> 00 | K7: =MID($A27,32,2) -> 00 | L7: =MID($A27,35,2) -> 1a | M7: =MID($A27,38,2) -> 04 | N7: =MID($A27,41,2) -> 17 | O7: =MID($A27,44,2) -> 06 | P7: =MID($A27,47,2) -> 00 | Q7: =MID($A27,50,2) -> 00 | S7: =TEXT(HEX2BIN(B7),"00000000") -> 00010000 | T7: =TEXT(HEX2BIN(C7),"00000000") -> 00000100 | U7: =TEXT(HEX2BIN(D7),"00000000") -> 00000010 | V7: =TEXT(HEX2BIN(E7),"00000000") -> 00001101 | W7: =TEXT(HEX2BIN(F7),"00000000") -> 00000001 | X7: =TEXT(HEX2BIN(G7),"00000000") -> 00000000 | Y7: =TEXT(HEX2BIN(H7),"00000000") -> 00000000 | Z7: =TEXT(HEX2BIN(I7),"00000000") -> 00000000 | ... AH7: =TEXT(HEX2BIN(Q7),"00000000") -> 00000000 | AL7: 0x04 [7:4] | AM7: iwol_out | AN7: don't care | AO7: =MID($W2,1,4) -> 1111 | AS7: 4'b0100 | AT7: SLED2 USE
A8: 60 | B8: =MID($A28,5,2) -> 10 | C8: =MID($A28,8,2) -> 00 | D8: =MID($A28,11,2) -> 02 | E8: =MID($A28,14,2) -> 18 | F8: =MID($A28,17,2) -> 01 | G8: =MID($A28,20,2) -> 00 | H8: =MID($A28,23,2) -> 00 | I8: =MID($A28,26,2) -> 00 | J8: =MID($A28,29,2) -> 00 | K8: =MID($A28,32,2) -> 00 | L8: =MID($A28,35,2) -> 1a | M8: =MID($A28,38,2) -> 04 | N8: =MID($A28,41,2) -> 17 | O8: =MID($A28,44,2) -> 06 | P8: =MID($A28,47,2) -> 00 | Q8: =MID($A28,50,2) -> 00 | S8: =TEXT(HEX2BIN(B8),"00000000") -> 00010000 | T8: =TEXT(HEX2BIN(C8),"00000000") -> 00000000 | U8: =TEXT(HEX2BIN(D8),"00000000") -> 00000010 | V8: =TEXT(HEX2BIN(E8),"00000000") -> 00011000 | W8: =TEXT(HEX2BIN(F8),"00000000") -> 00000001 | X8: =TEXT(HEX2BIN(G8),"00000000") -> 00000000 | Y8: =TEXT(HEX2BIN(H8),"00000000") -> 00000000 | Z8: =TEXT(HEX2BIN(I8),"00000000") -> 00000000 | ... AH8: =TEXT(HEX2BIN(Q8),"00000000") -> 00000000 | AL8: 0x04 [3:0] | AM8: iwol_in | AN8: don't care | AO8: =MID($W2,5,4) -> 1111 | AS8: 4'b1000 | AT8: SLED3 USE | AW8: Configuration | BC8: 0xC1[7:0] | BD8: Node ID:
A9: 70 | B9: =MID($A29,5,2) -> 00 | C9: =MID($A29,8,2) -> 00 | D9: =MID($A29,11,2) -> 00 | E9: =MID($A29,14,2) -> 00 | F9: =MID($A29,17,2) -> 00 | G9: =MID($A29,20,2) -> 00 | H9: =MID($A29,23,2) -> 00 | I9: =MID($A29,26,2) -> 00 | J9: =MID($A29,29,2) -> 00 | K9: =MID($A29,32,2) -> 00 | L9: =MID($A29,35,2) -> 00 | M9: =MID($A29,38,2) -> 00 | N9: =MID($A29,41,2) -> 00 | O9: =MID($A29,44,2) -> 00 | P9: =MID($A29,47,2) -> 00 | Q9: =MID($A29,50,2) -> 00 | S9: =TEXT(HEX2BIN(B9),"00000000") -> 00000000 | T9: =TEXT(HEX2BIN(C9),"00000000") -> 00000000 | U9: =TEXT(HEX2BIN(D9),"00000000") -> 00000000 | V9: =TEXT(HEX2BIN(E9),"00000000") -> 00000000 | W9: =TEXT(HEX2BIN(F9),"00000000") -> 00000000 | X9: =TEXT(HEX2BIN(G9),"00000000") -> 00000000 | Y9: =TEXT(HEX2BIN(H9),"00000000") -> 00000000 | Z9: =TEXT(HEX2BIN(I9),"00000000") -> 00000000 | ... AH9: =TEXT(HEX2BIN(Q9),"00000000") -> 00000000 | AV9: 0xC0 [3:2] | AW9: FRU ID Configuration | AX9: 00 | AY9: =MID($S14,5,2) -> 11 | AZ9: =IF(AY9="00","2S",IF(AY9="01","8S",IF(AY9="10","!!!D2ScheckFRU!!!",IF(AY9="11","4S","ERR")))) -> 4S | BC9: 0xC1 [7:6] | BD9: SLED3 Node ID
A10: 80 | B10: =MID($A30,5,2) -> 00 | C10: =MID($A30,8,2) -> 00 | D10: =MID($A30,11,2) -> 00 | E10: =MID($A30,14,2) -> 00 | F10: =MID($A30,17,2) -> 00 | G10: =MID($A30,20,2) -> 00 | H10: =MID($A30,23,2) -> 00 | I10: =MID($A30,26,2) -> 00 | J10: =MID($A30,29,2) -> 00 | K10: =MID($A30,32,2) -> 00 | L10: =MID($A30,35,2) -> 00 | M10: =MID($A30,38,2) -> 00 | N10: =MID($A30,41,2) -> 00 | O10: =MID($A30,44,2) -> 00 | P10: =MID($A30,47,2) -> 00 | Q10: =MID($A30,50,2) -> 00 | S10: =TEXT(HEX2BIN(B10),"00000000") -> 00000000 | T10: =TEXT(HEX2BIN(C10),"00000000") -> 00000000 | U10: =TEXT(HEX2BIN(D10),"00000000") -> 00000000 | V10: =TEXT(HEX2BIN(E10),"00000000") -> 00000000 | W10: =TEXT(HEX2BIN(F10),"00000000") -> 00000000 | X10: =TEXT(HEX2BIN(G10),"00000000") -> 00000000 | Y10: =TEXT(HEX2BIN(H10),"00000000") -> 00000000 | Z10: =TEXT(HEX2BIN(I10),"00000000") -> 00000000 | ... AH10: =TEXT(HEX2BIN(Q10),"00000000") -> 00000000 | AM10: power statue | AN10: only sled0 could read | AS10: 0x00[0] | AT10: FM_MISC_IOB_4S_N_8S_MODE | AV10: 0xC1 [7:0] | AW10: Node ID (from PCA9555) | AX10: 11100100 | AY10: =MID($T14,1,8) -> 11100100 | BC10: 0xC1 [5:4] | BD10: SLED2 Node ID
A11: 90 | B11: =MID($A31,5,2) -> 00 | C11: =MID($A31,8,2) -> 00 | D11: =MID($A31,11,2) -> 00 | E11: =MID($A31,14,2) -> 00 | F11: =MID($A31,17,2) -> 00 | G11: =MID($A31,20,2) -> 00 | H11: =MID($A31,23,2) -> 00 | I11: =MID($A31,26,2) -> 00 | J11: =MID($A31,29,2) -> 00 | K11: =MID($A31,32,2) -> 00 | L11: =MID($A31,35,2) -> 00 | M11: =MID($A31,38,2) -> 00 | N11: =MID($A31,41,2) -> 00 | O11: =MID($A31,44,2) -> 00 | P11: =MID($A31,47,2) -> 00 | Q11: =MID($A31,50,2) -> 00 | S11: =TEXT(HEX2BIN(B11),"00000000") -> 00000000 | T11: =TEXT(HEX2BIN(C11),"00000000") -> 00000000 | U11: =TEXT(HEX2BIN(D11),"00000000") -> 00000000 | V11: =TEXT(HEX2BIN(E11),"00000000") -> 00000000 | W11: =TEXT(HEX2BIN(F11),"00000000") -> 00000000 | X11: =TEXT(HEX2BIN(G11),"00000000") -> 00000000 | Y11: =TEXT(HEX2BIN(H11),"00000000") -> 00000000 | Z11: =TEXT(HEX2BIN(I11),"00000000") -> 00000000 | ... AH11: =TEXT(HEX2BIN(Q11),"00000000") -> 00000000 | AL11: 0x05 [8:0] | AN11: =TEXT(11111111,"00000000") -> 11111111 | AO11: =MID(X2,1,8) -> 00110011 | AS11: 1'b0 | AT11: 2S/4S | AV11: 0xC2 [7:4] | AW11: CPU1_SKTOCC information | AX11: check CPU set | AY11: =MID($U14,1,4) -> 1100 | AZ11: =IF(AY11="1110", "CPU0-set2s", IF(AY11="1100", "CPU0-set4s", IF(AY11="0000", "CPU0-set8s", "CPU0 set error"))) -> CPU0-set4s | BC11: 0xC1 [3:2] | BD11: SLED1 Node ID
A12: a0 | B12: =MID($A32,5,2) -> 00 | C12: =MID($A32,8,2) -> 00 | D12: =MID($A32,11,2) -> 00 | E12: =MID($A32,14,2) -> 00 | F12: =MID($A32,17,2) -> 00 | G12: =MID($A32,20,2) -> 00 | H12: =MID($A32,23,2) -> 31 | I12: =MID($A32,26,2) -> 00 | J12: =MID($A32,29,2) -> d1 | K12: =MID($A32,32,2) -> 00 | L12: =MID($A32,35,2) -> 00 | M12: =MID($A32,38,2) -> 00 | N12: =MID($A32,41,2) -> 00 | O12: =MID($A32,44,2) -> 00 | P12: =MID($A32,47,2) -> 00 | Q12: =MID($A32,50,2) -> 00 | S12: =TEXT(HEX2BIN(B12),"00000000") -> 00000000 | T12: =TEXT(HEX2BIN(C12),"00000000") -> 00000000 | U12: =TEXT(HEX2BIN(D12),"00000000") -> 00000000 | V12: =TEXT(HEX2BIN(E12),"00000000") -> 00000000 | W12: =TEXT(HEX2BIN(F12),"00000000") -> 00000000 | X12: =TEXT(HEX2BIN(G12),"00000000") -> 00000000 | Y12: =TEXT(HEX2BIN(H12),"00000000") -> 00110001 | Z12: =TEXT(HEX2BIN(I12),"00000000") -> 00000000 | ... AH12: =TEXT(HEX2BIN(Q12),"00000000") -> 00000000 | AL12: 0x05[7] | AM12: iVPDB_P12V_AUX4_VR_ALERT_N | AN12: =MID(AN11,1,1) -> 1 | AO12: =MID(AO11,1,1) -> 0 | AQ12: loc="R5" | AS12: 1'b1 | AT12: 8S | AV12: 0xC2[3:0] | AW12: CPU0_SKTOCC information | AX12: check CPU set | AY12: =MID($U14,5,8) -> 1100 | AZ12: =IF(AY12="1110", "CPU1-set2s", IF(AY12="1100", "CPU1-set4s", IF(AY12="0000", "CPU1-set8s", "CPU1 set error"))) -> CPU1-set4s | BC12: 0xC1 [1:0] | BD12: SLED0 Node ID
A13: b0 | B13: =MID($A33,5,2) -> 00 | C13: =MID($A33,8,2) -> 00 | D13: =MID($A33,11,2) -> 00 | E13: =MID($A33,14,2) -> 00 | F13: =MID($A33,17,2) -> 00 | G13: =MID($A33,20,2) -> 00 | H13: =MID($A33,23,2) -> 00 | I13: =MID($A33,26,2) -> 00 | J13: =MID($A33,29,2) -> 00 | K13: =MID($A33,32,2) -> 00 | L13: =MID($A33,35,2) -> 00 | M13: =MID($A33,38,2) -> 00 | N13: =MID($A33,41,2) -> 00 | O13: =MID($A33,44,2) -> 00 | P13: =MID($A33,47,2) -> 00 | Q13: =MID($A33,50,2) -> 00 | S13: =TEXT(HEX2BIN(B13),"00000000") -> 00000000 | T13: =TEXT(HEX2BIN(C13),"00000000") -> 00000000 | U13: =TEXT(HEX2BIN(D13),"00000000") -> 00000000 | V13: =TEXT(HEX2BIN(E13),"00000000") -> 00000000 | W13: =TEXT(HEX2BIN(F13),"00000000") -> 00000000 | X13: =TEXT(HEX2BIN(G13),"00000000") -> 00000000 | Y13: =TEXT(HEX2BIN(H13),"00000000") -> 00000000 | Z13: =TEXT(HEX2BIN(I13),"00000000") -> 00000000 | ... AH13: =TEXT(HEX2BIN(Q13),"00000000") -> 00000000 | AL13: 0x05[6] | AM13: iVPDB_P12V_AUX3_VR_ALERT_N | AN13: =MID(AN11,2,1) -> 1 | AO13: =MID(AO11,2,1) -> 0 | AQ13: loc="V7" | AW13: FRU ID Configuration - C4XAB
A14: c0 | B14: =MID($A34,5,2) -> 0c | C14: =MID($A34,8,2) -> e4 | D14: =MID($A34,11,2) -> cc | E14: =MID($A34,14,2) -> 43 | F14: =MID($A34,17,2) -> 34 | G14: =MID($A34,20,2) -> 33 | H14: =MID($A34,23,2) -> 41 | I14: =MID($A34,26,2) -> 42 | J14: =MID($A34,29,2) -> 00 | K14: =MID($A34,32,2) -> 00 | L14: =MID($A34,35,2) -> 00 | M14: =MID($A34,38,2) -> 00 | N14: =MID($A34,41,2) -> 00 | O14: =MID($A34,44,2) -> 00 | P14: =MID($A34,47,2) -> 00 | Q14: =MID($A34,50,2) -> 00 | S14: =TEXT(HEX2BIN(B14),"00000000") -> 00001100 | T14: =TEXT(HEX2BIN(C14),"00000000") -> 11100100 | U14: =TEXT(HEX2BIN(D14),"00000000") -> 11001100 | V14: =TEXT(HEX2BIN(E14),"00000000") -> 01000011 | W14: =TEXT(HEX2BIN(F14),"00000000") -> 00110100 | X14: =TEXT(HEX2BIN(G14),"00000000") -> 00110011 | Y14: =TEXT(HEX2BIN(H14),"00000000") -> 01000001 | Z14: =TEXT(HEX2BIN(I14),"00000000") -> 01000010 | ... AH14: =TEXT(HEX2BIN(Q14),"00000000") -> 00000000 | AL14: 0x05[5] | AM14: iHPDB_P12V_AUX2_VR_ALERT_N | AN14: =MID(AN11,3,1) -> 1 | AO14: =MID(AO11,3,1) -> 1 | AQ14: loc="E22" | AS14: 0x19[7:0] | AT14: FAN_DUTY_SET: | AV14: 0xC3 [7:0] | AW14: FRU ID Configuration - C | AX14: 43 | AY14: =E14 -> 43 | AZ14: {=_xlfn.TEXTJOIN("", TRUE, MID(CHAR(HEX2DEC(MID(AY14, ROW(INDIRECT("1:" & LEN(AY14)/2))*2-1, 2))), 1, 1))} -> C | BC14: 0xC2[7:4] | BD14: CPU_SKTOCC: (1: NO CPU , 0: CPU install)
A15: d0 | B15: =MID($A35,5,2) -> 00 | C15: =MID($A35,8,2) -> 00 | D15: =MID($A35,11,2) -> 00 | E15: =MID($A35,14,2) -> 00 | F15: =MID($A35,17,2) -> 00 | G15: =MID($A35,20,2) -> 00 | H15: =MID($A35,23,2) -> 00 | I15: =MID($A35,26,2) -> 00 | J15: =MID($A35,29,2) -> 00 | K15: =MID($A35,32,2) -> 00 | L15: =MID($A35,35,2) -> 00 | M15: =MID($A35,38,2) -> 00 | N15: =MID($A35,41,2) -> 00 | O15: =MID($A35,44,2) -> 00 | P15: =MID($A35,47,2) -> 00 | Q15: =MID($A35,50,2) -> 00 | S15: =TEXT(HEX2BIN(B15),"00000000") -> 00000000 | T15: =TEXT(HEX2BIN(C15),"00000000") -> 00000000 | U15: =TEXT(HEX2BIN(D15),"00000000") -> 00000000 | V15: =TEXT(HEX2BIN(E15),"00000000") -> 00000000 | W15: =TEXT(HEX2BIN(F15),"00000000") -> 00000000 | X15: =TEXT(HEX2BIN(G15),"00000000") -> 00000000 | Y15: =TEXT(HEX2BIN(H15),"00000000") -> 00000000 | Z15: =TEXT(HEX2BIN(I15),"00000000") -> 00000000 | ... AH15: =TEXT(HEX2BIN(Q15),"00000000") -> 00000000 | AL15: 0x05[4] | AM15: iHPDB_P12V_AUX1_VR_ALERT_N | AN15: =MID(AN11,4,1) -> 1 | AO15: =MID(AO11,4,1) -> 1 | AQ15: loc="J22" | AS15: 8'h0 | AT15: 0.01 | AV15: 0xC4 [7:0] | AW15: FRU ID Configuration - 4 | AX15: 34 | AY15: =F14 -> 34 | AZ15: {=_xlfn.TEXTJOIN("", TRUE, MID(CHAR(HEX2DEC(MID(AY15, ROW(INDIRECT("1:" & LEN(AY15)/2))*2-1, 2))), 1, 1))} -> 4 | BC15: 0xC2[7] | BD15: SLED3 CPU0
A16: e0 | B16: =MID($A36,5,2) -> 00 | C16: =MID($A36,8,2) -> 00 | D16: =MID($A36,11,2) -> 00 | E16: =MID($A36,14,2) -> 00 | F16: =MID($A36,17,2) -> 00 | G16: =MID($A36,20,2) -> 00 | H16: =MID($A36,23,2) -> 00 | I16: =MID($A36,26,2) -> 00 | J16: =MID($A36,29,2) -> 00 | K16: =MID($A36,32,2) -> 00 | L16: =MID($A36,35,2) -> 00 | M16: =MID($A36,38,2) -> 00 | N16: =MID($A36,41,2) -> 00 | O16: =MID($A36,44,2) -> 00 | P16: =MID($A36,47,2) -> 00 | Q16: =MID($A36,50,2) -> 00 | S16: =TEXT(HEX2BIN(B16),"00000000") -> 00000000 | T16: =TEXT(HEX2BIN(C16),"00000000") -> 00000000 | U16: =TEXT(HEX2BIN(D16),"00000000") -> 00000000 | V16: =TEXT(HEX2BIN(E16),"00000000") -> 00000000 | W16: =TEXT(HEX2BIN(F16),"00000000") -> 00000000 | X16: =TEXT(HEX2BIN(G16),"00000000") -> 00000000 | Y16: =TEXT(HEX2BIN(H16),"00000000") -> 00000000 | Z16: =TEXT(HEX2BIN(I16),"00000000") -> 00000000 | ... AH16: =TEXT(HEX2BIN(Q16),"00000000") -> 00000000 | AL16: 0x05[3] | AM16: iNODE3_FPGA_ROT_P1_RST_N | AN16: =MID(AN11,5,1) -> 1 | AO16: =MID(AO11,5,1) -> 0 | AQ16: loc="U17" | AS16: 8'h64 | AT16: 1 | AV16: 0xC5 [7:0] | AW16: FRU ID Configuration - X | AX16: 2S-31/4S-33/8S-36 | AY16: =G14 -> 33 | AZ16: {=_xlfn.TEXTJOIN("", TRUE, MID(CHAR(HEX2DEC(MID(AY16, ROW(INDIRECT("1:" & LEN(AY16)/2))*2-1, 2))), 1, 1))} -> 3 | BC16: 0xC2[6] | BD16: SLED2 CPU0
A17: f0 | B17: =MID($A37,5,2) -> cd | C17: =MID($A37,8,2) -> 1f | D17: =MID($A37,11,2) -> 1f | E17: =MID($A37,14,2) -> 00 | F17: =MID($A37,17,2) -> 00 | G17: =MID($A37,20,2) -> 00 | H17: =MID($A37,23,2) -> 00 | I17: =MID($A37,26,2) -> 00 | J17: =MID($A37,29,2) -> 00 | K17: =MID($A37,32,2) -> 00 | L17: =MID($A37,35,2) -> 00 | M17: =MID($A37,38,2) -> 00 | N17: =MID($A37,41,2) -> 00 | O17: =MID($A37,44,2) -> 00 | P17: =MID($A37,47,2) -> 02 | Q17: =MID($A37,50,2) -> 0a | S17: =TEXT(HEX2BIN(B17),"00000000") -> 11001101 | T17: =TEXT(HEX2BIN(C17),"00000000") -> 00011111 | U17: =TEXT(HEX2BIN(D17),"00000000") -> 00011111 | V17: =TEXT(HEX2BIN(E17),"00000000") -> 00000000 | W17: =TEXT(HEX2BIN(F17),"00000000") -> 00000000 | X17: =TEXT(HEX2BIN(G17),"00000000") -> 00000000 | Y17: =TEXT(HEX2BIN(H17),"00000000") -> 00000000 | Z17: =TEXT(HEX2BIN(I17),"00000000") -> 00000000 | ... AH17: =TEXT(HEX2BIN(Q17),"00000000") -> 00001010 | AL17: 0x05[2] | AM17: iNODE2_FPGA_ROT_P1_RST_N | AN17: =MID(AN11,6,1) -> 1 | AO17: =MID(AO11,6,1) -> 0 | AQ17: loc="P3" | AV17: 0xC6 [7:0] | AW17: FRU ID Configuration - A | AX17: 41 | AY17: =H14 -> 41 | AZ17: {=_xlfn.TEXTJOIN("", TRUE, MID(CHAR(HEX2DEC(MID(AY17, ROW(INDIRECT("1:" & LEN(AY17)/2))*2-1, 2))), 1, 1))} -> A | BC17: 0xC2[5] | BD17: SLED1 CPU0
AL18: 0x05[1] | AM18: iNODE1_FPGA_ROT_P1_RST_N | AN18: =MID(AN11,7,1) -> 1 | AO18: =MID(AO11,7,1) -> 1 | AQ18: loc="A3" | AV18: 0xC7 [7:0] | AW18: FRU ID Configuration - B | AX18: 42 | AY18: =I14 -> 42 | AZ18: {=_xlfn.TEXTJOIN("", TRUE, MID(CHAR(HEX2DEC(MID(AY18, ROW(INDIRECT("1:" & LEN(AY18)/2))*2-1, 2))), 1, 1))} -> B | BC18: 0xC2[4] | BD18: SLE0 CPU0
AL19: 0x05[0] | AM19: iNODE0_FPGA_ROT_P1_RST_N | AN19: =MID(AN11,8,1) -> 1 | AO19: =MID(AO11,8,1) -> 1 | AQ19: loc="A16"
A20: Paste LOG Here ( i2cdump -y -a -f 6 0x30 ) | AL20: 0x06 [8:0] | AN20: =TEXT(11111111,"00000000") -> 11111111 | AO20: =MID(Y2,1,8) -> 00001111 | AW20: power statue | BC20: 0xC2[3:0] | BD20: CPU_SKTOCC: (1: NO CPU , 0: CPU install)
A21: 0 1 2 3 4 5 6 7 8 9 a b c d e f 0123456789abcdef | AL21: 0x06[7] | AM21: iVPDB_P48V_AUX4_UV_ALERT2_N | AN21: =MID(AN20,1,1) -> 1 | AO21: =MID(AO20,1,1) -> 0 | AQ21: loc="V4" | AV21: 0xF1 [8:0] | AX21: 11xx1101 | AY21: =MID(S17,1,8) -> 11001101 | BC21: 0xC2[3] | BD21: SLED3 CPU1
A22: 00: 10 00 00 00 ff 33 0f ff ff ff ff 00 00 00 00 00 ?....s?......... | AL22: 0x06[6] | AM22: iVPDB_P48V_AUX4_OC_ALERT1_N | AN22: =MID(AN20,2,1) -> 1 | AO22: =MID(AO20,2,1) -> 0 | AQ22: loc="U5" | AV22: 0xF0[7] | AW22: HPDB_P48V_AUX1_HS_FAULT_N | AX22: =MID(AX21,1,1) -> 1 | AY22: =MID(AY21,1,1) -> 1 | BA22: loc="F8" | BC22: 0xC2[2] | BD22: SLED2 CPU1
A23: 10: 00 00 00 00 00 00 00 00 00 64 06 1e 00 0f 02 00 .........d??.??. | AL23: 0x06[5] | AM23: iVPDB_P48V_AUX3_UV_ALERT2_N | AN23: =MID(AN20,3,1) -> 1 | AO23: =MID(AO20,3,1) -> 0 | AQ23: loc="U12" | AV23: 0xF0[6] | AW23: HPDB_P48V_AUX2_HS_FAULT_N | AX23: =MID(AX21,2,1) -> 1 | AY23: =MID(AY21,2,1) -> 1 | BA23: loc="L7" | BC23: 0xC2[1] | BD23: SLED1 CPU1
A24: 20: 00 00 00 00 00 00 00 00 00 00 00 00 00 00 00 00 ................ | AL24: 0x06[4] | AM24: iVPDB_P48V_AUX3_OC_ALERT1_N | AN24: =MID(AN20,4,1) -> 1 | AO24: =MID(AO20,4,1) -> 0 | AQ24: loc="V12" | AV24: 0xF0[5] | AW24: VPDB_P48V_AUX3_HS_FAULT_N | AX24: =IF(AY9="01","1","0") -> 0 | AY24: =MID(AY21,3,1) -> 0 | BA24: loc="U11" | BC24: 0xC2[0] | BD24: SLE0 CPU1
A25: 30: 00 00 00 00 2d 90 00 00 00 00 f0 00 00 00 00 00 ....-?....?..... | AL25: 0x06[3] | AM25: iHPDB_P48V_AUX2_UV_ALERT2_N | AN25: =MID(AN20,5,1) -> 1 | AO25: =MID(AO20,5,1) -> 1 | AQ25: loc="J7" | AV25: 0xF0[4] | AW25: VPDB_P48V_AUX4_HS_FAULT_N | AX25: =IF(AY9="01","1","0") -> 0 | AY25: =MID(AY21,4,1) -> 0 | BA25: loc="P5"
A26: 40: 10 00 00 00 00 00 00 00 00 00 00 00 00 00 00 00 ?............... | AL26: 0x06[2] | AM26: iHPDB_P48V_AUX2_OC_ALERT1_N | AN26: =MID(AN20,6,1) -> 1 | AO26: =MID(AO20,6,1) -> 1 | AQ26: loc="K7" | AV26: 0xF0[3] | AW26: PWRGD_P12V_AUX1 | AX26: =MID(AX21,5,1) -> 1 | AY26: =MID(AY21,5,1) -> 1 | BA26: loc="E7"
A27: 50: 10 04 02 0d 01 00 00 00 00 00 1a 04 17 06 00 00 ?????.....????.. | AL27: 0x06[1] | AM27: iHPDB_P48V_AUX1_UV_ALERT2_N | AN27: =MID(AN20,7,1) -> 1 | AO27: =MID(AO20,7,1) -> 1 | AQ27: loc="C9" | AV27: 0xF0[2] | AW27: PWRGD_P12V_AUX2 | AX27: =MID(AX21,6,1) -> 1 | AY27: =MID(AY21,6,1) -> 1 | BA27: loc="P7"
A28: 60: 10 00 02 18 01 00 00 00 00 00 1a 04 17 06 00 00 ?.???.....????.. | AL28: 0x06[0] | AM28: iHPDB_P48V_AUX1_OC_ALERT1_N | AN28: =MID(AN20,8,1) -> 1 | AO28: =MID(AO20,8,1) -> 1 | AQ28: loc="C8" | AV28: 0xF0[1] | AW28: fru_flash_sel | AX28: =MID(AX21,7,1) -> 0 | AY28: =MID(AY21,7,1) -> 0
A29: 70: 00 00 00 00 00 00 00 00 00 00 00 00 00 00 00 00 ................ | AV29: 0xF0[0] | AW29: BMC_GFPGA_MUX_SEL | AX29: =MID(AX21,8,1) -> 1 | AY29: =MID(AY21,8,1) -> 1
A30: 80: 00 00 00 00 00 00 00 00 00 00 00 00 00 00 00 00 ................ | AM30: power statue
A31: 90: 00 00 00 00 00 00 00 00 00 00 00 00 00 00 00 00 ................ | AL31: 0x18 [7] | AM31: FAN_PWM_SEL | AN31: 0 | AO31: =MID($AA3,1,1) -> 0 | AW31: GLB_THROTTLE/GLB_PWRBRK
A32: a0: 00 00 00 00 00 00 31 00 d1 00 00 00 00 00 00 00 ......1.?....... | AL32: 0x18 [6] | AM32: FAN_PWM_CTRL | AN32: 0 | AO32: =MID($AA3,2,1) -> 0 | AV32: 0xF1 [8:0] | AW32: GLB_THROTTLE_R_N_S_All | AX32: =TEXT(1111111,"00000000") -> 01111111 | AY32: =MID($T17,1,8) -> 00011111
A33: b0: 00 00 00 00 00 00 00 00 00 00 00 00 00 00 00 00 ................ | AL33: 0x18 [5:0] | AM33: FAN_FREQ_SET | AN33: 000000 | AO33: =MID($AA3,3,8) -> 000000 | AV33: 0xF1[7] | AW33: Reserved as '0' | AX33: =MID(AX32,1,1) -> 0 | AY33: =MID(AY32,1,1) -> 0
A34: c0: 0c e4 cc 43 34 33 41 42 00 00 00 00 00 00 00 00 ???C43AB........ | AL34: 0x19 [7:0] | AM34: FAN_DUTY_SET | AN34: don't care | AO34: =MID($K3,1,8) -> 64 | AP34: =TEXT(HEX2DEC(AO34)/100,"0.00%") -> 100.00% | AV34: 0xF1[6] | AW34: PWRGD_P12V_AUX4 | AX34: =MID(AX32,2,1) -> 1 | AY34: =MID(AY32,2,1) -> 0 | BA34: loc="H16"
A35: d0: 00 00 00 00 00 00 00 00 00 00 00 00 00 00 00 00 ................ | AL35: 0x1A [7:0] | AM35: FAN_WDG_CNT | AN35: 00 | AO35: =MID($L3,1,8) -> 06 | AV35: 0xF1[5] | AW35: PWRGD_P12V_AUX3 | AX35: =MID(AX32,3,1) -> 1 | AY35: =MID(AY32,3,1) -> 0 | BA35: loc="H17"
A36: e0: 00 00 00 00 00 00 00 00 00 00 00 00 00 00 00 00 ................ | AL36: 0x1B [7:0] | AM36: FAN_WDG | AN36: 1e | AO36: =MID($M3,1,8) -> 1e | AV36: 0xF1[4] | AW36: GLB_THROTTLE_R_N_S_All | AX36: =MID(AX32,4,1) -> 1 | AY36: =MID(AY32,4,1) -> 1
A37: f0: cd 1f 1f 00 00 00 00 00 00 00 00 00 00 00 02 0a ???...........?? | AV37: 0xF1[3] | AW37: GLB_THROTTLE_R_N_S_SLED3 | AX37: =MID(AX32,5,1) -> 1 | AY37: =MID(AY32,5,1) -> 1 | AZ37: =IF(BIN2DEC(AY37)=1,"stable","!SLED3 trottle!") -> stable
AM38: sync | AV38: 0xF1[2] | AW38: GLB_THROTTLE_R_N_S_SLED2 | AX38: =MID(AX32,6,1) -> 1 | AY38: =MID(AY32,6,1) -> 1 | AZ38: =IF(BIN2DEC(AY38)=1,"stable","!SLED2 trottle!") -> stable
AL39: 0x1D [8:0] | AN39: =TEXT(11111111,"00000000") -> 11111111 | AO39: =MID(AF3,1,8) -> 00001111 | AV39: 0xF1[1] | AW39: GLB_THROTTLE_R_N_S_SLED1 | AX39: =MID(AX32,7,1) -> 1 | AY39: =MID(AY32,7,1) -> 1 | AZ39: =IF(BIN2DEC(AY39)=1,"stable","!SLED1 trottle!") -> stable
AL40: 0x1D[7] | AM40: ifm_hpm_stby_rst_node3_global_ack | AN40: =MID(AN39,1,1) -> 1 | AO40: =MID(AO39,1,1) -> 0 | AQ40: loc="AA4" | AV40: 0xF1[0] | AW40: GLB_THROTTLE_R_N_S_SLED0 | AX40: =MID(AX32,8,1) -> 1 | AY40: =MID(AY32,8,1) -> 1 | AZ40: =IF(BIN2DEC(AY40)=1,"stable","!SLED0 trottle!") -> stable
...

Sheet SCM reg
A1: LOG | B1: 0 | C1: 1 | D1: 2 | E1: 3 | F1: 4 | G1: 5 | H1: 6 | I1: 7 | J1: 8 | K1: 9 | L1: A | M1: B | N1: C | O1: D | P1: E | Q1: F | S1: 0 | T1: 1 | U1: 2 | V1: 3 | W1: 4 | X1: 5 | Y1: 6 | Z1: 7 | AA1: 8 | AB1: 9 | AC1: A | AD1: B | AE1: C | AF1: D | AG1: E | AH1: F
A2: 0 | B2: =MID($A22,5,2) -> 36 | C2: =MID($A22,8,2) -> 01 | D2: =MID($A22,11,2) -> 01 | E2: =MID($A22,14,2) -> 0f | F2: =MID($A22,17,2) -> 03 | G2: =MID($A22,20,2) -> 00 | H2: =MID($A22,23,2) -> 00 | I2: =MID($A22,26,2) -> 00 | J2: =MID($A22,29,2) -> 86 | K2: =MID($A22,32,2) -> cd | L2: =MID($A22,35,2) -> 09 | M2: =MID($A22,38,2) -> ff | N2: =MID($A22,41,2) -> 1b | O2: =MID($A22,44,2) -> 00 | P2: =MID($A22,47,2) -> 00 | Q2: =MID($A22,50,2) -> 00 | S2: =TEXT(HEX2BIN(B2),"00000000") -> 00110110 | T2: =TEXT(HEX2BIN(C2),"00000000") -> 00000001 | U2: =TEXT(HEX2BIN(D2),"00000000") -> 00000001 | V2: =TEXT(HEX2BIN(E2),"00000000") -> 00001111 | W2: =TEXT(HEX2BIN(F2),"00000000") -> 00000011 | X2: =TEXT(HEX2BIN(G2),"00000000") -> 00000000 | Y2: =TEXT(HEX2BIN(H2),"00000000") -> 00000000 | Z2: =TEXT(HEX2BIN(I2),"00000000") -> 00000000 | ... AH2: =TEXT(HEX2BIN(Q2),"00000000") -> 00000000 | AV2: SGPIO DATA Detail
A3: 10 | B3: =MID($A23,5,2) -> bf | C3: =MID($A23,8,2) -> be | D3: =MID($A23,11,2) -> eb | E3: =MID($A23,14,2) -> f8 | F3: =MID($A23,17,2) -> ff | G3: =MID($A23,20,2) -> ff | H3: =MID($A23,23,2) -> ff | I3: =MID($A23,26,2) -> f7 | J3: =MID($A23,29,2) -> 9f | K3: =MID($A23,32,2) -> 0f | L3: =MID($A23,35,2) -> 00 | M3: =MID($A23,38,2) -> 00 | N3: =MID($A23,41,2) -> 00 | O3: =MID($A23,44,2) -> 00 | P3: =MID($A23,47,2) -> 00 | Q3: =MID($A23,50,2) -> 00 | S3: =TEXT(HEX2BIN(B3),"00000000") -> 10111111 | T3: =TEXT(HEX2BIN(C3),"00000000") -> 10111110 | U3: =TEXT(HEX2BIN(D3),"00000000") -> 11101011 | V3: =TEXT(HEX2BIN(E3),"00000000") -> 11111000 | W3: =TEXT(HEX2BIN(F3),"00000000") -> 11111111 | X3: =TEXT(HEX2BIN(G3),"00000000") -> 11111111 | Y3: =TEXT(HEX2BIN(H3),"00000000") -> 11111111 | Z3: =TEXT(HEX2BIN(I3),"00000000") -> 11110111 | ... AH3: =TEXT(HEX2BIN(Q3),"00000000") -> 00000000 | AM3: Common info | AX3: Common info | BA3: EXP. | BB3: Data. | BH3: Common info | BK3: EXP. | BL3: Data.
A4: 20 | B4: =MID($A24,5,2) -> 63 | C4: =MID($A24,8,2) -> 4c | D4: =MID($A24,11,2) -> de | E4: =MID($A24,14,2) -> ce | F4: =MID($A24,17,2) -> 7f | G4: =MID($A24,20,2) -> 0d | H4: =MID($A24,23,2) -> 00 | I4: =MID($A24,26,2) -> 00 | J4: =MID($A24,29,2) -> fe | K4: =MID($A24,32,2) -> 1f | L4: =MID($A24,35,2) -> 00 | M4: =MID($A24,38,2) -> 00 | N4: =MID($A24,41,2) -> 00 | O4: =MID($A24,44,2) -> 00 | P4: =MID($A24,47,2) -> 00 | Q4: =MID($A24,50,2) -> 00 | S4: =TEXT(HEX2BIN(B4),"00000000") -> 01100011 | T4: =TEXT(HEX2BIN(C4),"00000000") -> 01001100 | U4: =TEXT(HEX2BIN(D4),"00000000") -> 11011110 | V4: =TEXT(HEX2BIN(E4),"00000000") -> 11001110 | W4: =TEXT(HEX2BIN(F4),"00000000") -> 01111111 | X4: =TEXT(HEX2BIN(G4),"00000000") -> 00001101 | Y4: =TEXT(HEX2BIN(H4),"00000000") -> 00000000 | Z4: =TEXT(HEX2BIN(I4),"00000000") -> 00000000 | ... AH4: =TEXT(HEX2BIN(Q4),"00000000") -> 00000000 | AM4: CPLD Revision | AN4: EXP. | AO4: Data. | AP4: Analyze | AW4: 0x10 [7:0] | AX4: Check SGPIO 0 Data | BA4: =AN25 -> 10111111 | BB4: =AO25 -> 10111111 | BG4: 0x20 [7:0] | BH4: Check SGPIO 0 Data | BK4: =AN36 -> 01100100 | BL4: =AO36 -> 01100011
A5: 30 | B5: =MID($A25,5,2) -> 00 | C5: =MID($A25,8,2) -> 00 | D5: =MID($A25,11,2) -> f9 | E5: =MID($A25,14,2) -> 0b | F5: =MID($A25,17,2) -> 00 | G5: =MID($A25,20,2) -> 00 | H5: =MID($A25,23,2) -> 00 | I5: =MID($A25,26,2) -> 00 | J5: =MID($A25,29,2) -> 00 | K5: =MID($A25,32,2) -> 00 | L5: =MID($A25,35,2) -> 00 | M5: =MID($A25,38,2) -> 00 | N5: =MID($A25,41,2) -> 00 | O5: =MID($A25,44,2) -> 00 | P5: =MID($A25,47,2) -> 00 | Q5: =MID($A25,50,2) -> 00 | S5: =TEXT(HEX2BIN(B5),"00000000") -> 00000000 | T5: =TEXT(HEX2BIN(C5),"00000000") -> 00000000 | U5: =TEXT(HEX2BIN(D5),"00000000") -> 11111001 | V5: =TEXT(HEX2BIN(E5),"00000000") -> 00001011 | W5: =TEXT(HEX2BIN(F5),"00000000") -> 00000000 | X5: =TEXT(HEX2BIN(G5),"00000000") -> 00000000 | Y5: =TEXT(HEX2BIN(H5),"00000000") -> 00000000 | Z5: =TEXT(HEX2BIN(I5),"00000000") -> 00000000 | ... AH5: =TEXT(HEX2BIN(Q5),"00000000") -> 00000000 | AL5: 0x00 [7:4] | AM5: Major Revision | AN5: 3 | AO5: =MID($B2,1,1) -> 3 | AW5: 0x10 [7] | AX5: P0_PROCHOT_N | BA5: =MID($BA4,1,1) -> 1 | BB5: =MID($BB4,1,1) -> 1 | BG5: 0x20 [7] | BH5: PDB_ALERT3_EN_N | BK5: =MID($BK4,1,1) -> 0 | BL5: =MID($BL4,1,1) -> 0
A6: 40 | B6: =MID($A26,5,2) -> 10 | C6: =MID($A26,8,2) -> 00 | D6: =MID($A26,11,2) -> 00 | E6: =MID($A26,14,2) -> 00 | F6: =MID($A26,17,2) -> 00 | G6: =MID($A26,20,2) -> 00 | H6: =MID($A26,23,2) -> 00 | I6: =MID($A26,26,2) -> 00 | J6: =MID($A26,29,2) -> 00 | K6: =MID($A26,32,2) -> 00 | L6: =MID($A26,35,2) -> 00 | M6: =MID($A26,38,2) -> 00 | N6: =MID($A26,41,2) -> 00 | O6: =MID($A26,44,2) -> 00 | P6: =MID($A26,47,2) -> 00 | Q6: =MID($A26,50,2) -> 00 | S6: =TEXT(HEX2BIN(B6),"00000000") -> 00010000 | T6: =TEXT(HEX2BIN(C6),"00000000") -> 00000000 | U6: =TEXT(HEX2BIN(D6),"00000000") -> 00000000 | V6: =TEXT(HEX2BIN(E6),"00000000") -> 00000000 | W6: =TEXT(HEX2BIN(F6),"00000000") -> 00000000 | X6: =TEXT(HEX2BIN(G6),"00000000") -> 00000000 | Y6: =TEXT(HEX2BIN(H6),"00000000") -> 00000000 | Z6: =TEXT(HEX2BIN(I6),"00000000") -> 00000000 | ... AH6: =TEXT(HEX2BIN(Q6),"00000000") -> 00000000 | AL6: 0x00 [3:0] | AM6: Minor Revision | AN6: 4 | AO6: =MID($B2,2,1) -> 6 | AR6: SGPIO Link Status: | AW6: 0x10 [5] | AX6: P0_BMC_MEMTRIP_N | BA6: =MID($BA4,3,1) -> 1 | BB6: =MID($BB4,3,1) -> 1 | BG6: 0x20 [6] | BH6: PDB_ALERT2_EN_N | BK6: =MID($BK4,2,1) -> 1 | BL6: =MID($BL4,2,1) -> 1
A7: 50 | B7: =MID($A27,5,2) -> 00 | C7: =MID($A27,8,2) -> 00 | D7: =MID($A27,11,2) -> 00 | E7: =MID($A27,14,2) -> 00 | F7: =MID($A27,17,2) -> 00 | G7: =MID($A27,20,2) -> 00 | H7: =MID($A27,23,2) -> 00 | I7: =MID($A27,26,2) -> 00 | J7: =MID($A27,29,2) -> 00 | K7: =MID($A27,32,2) -> 00 | L7: =MID($A27,35,2) -> 00 | M7: =MID($A27,38,2) -> 00 | N7: =MID($A27,41,2) -> 00 | O7: =MID($A27,44,2) -> 00 | P7: =MID($A27,47,2) -> 00 | Q7: =MID($A27,50,2) -> 00 | S7: =TEXT(HEX2BIN(B7),"00000000") -> 00000000 | T7: =TEXT(HEX2BIN(C7),"00000000") -> 00000000 | U7: =TEXT(HEX2BIN(D7),"00000000") -> 00000000 | V7: =TEXT(HEX2BIN(E7),"00000000") -> 00000000 | W7: =TEXT(HEX2BIN(F7),"00000000") -> 00000000 | X7: =TEXT(HEX2BIN(G7),"00000000") -> 00000000 | Y7: =TEXT(HEX2BIN(H7),"00000000") -> 00000000 | Z7: =TEXT(HEX2BIN(I7),"00000000") -> 00000000 | ... AH7: =TEXT(HEX2BIN(Q7),"00000000") -> 00000000 | AM7: SGPIO Control / Status | AR7: 2'b00 | AS7: Off | AW7: 0x10 [4] | AX7: H_CPU0_MEMHOT_OUT_LVC1_N | BA7: =MID($BA4,4,1) -> 1 | BB7: =MID($BB4,4,1) -> 1 | BG7: 0x20 [5] | BH7: RST_MIC_MUX_N | BK7: =MID($BK4,3,1) -> 1 | BL7: =MID($BL4,3,1) -> 1
A8: 60 | B8: =MID($A28,5,2) -> 00 | C8: =MID($A28,8,2) -> 00 | D8: =MID($A28,11,2) -> 00 | E8: =MID($A28,14,2) -> 00 | F8: =MID($A28,17,2) -> 00 | G8: =MID($A28,20,2) -> 00 | H8: =MID($A28,23,2) -> 00 | I8: =MID($A28,26,2) -> 00 | J8: =MID($A28,29,2) -> 00 | K8: =MID($A28,32,2) -> 00 | L8: =MID($A28,35,2) -> 00 | M8: =MID($A28,38,2) -> 00 | N8: =MID($A28,41,2) -> 00 | O8: =MID($A28,44,2) -> 00 | P8: =MID($A28,47,2) -> 00 | Q8: =MID($A28,50,2) -> 00 | S8: =TEXT(HEX2BIN(B8),"00000000") -> 00000000 | T8: =TEXT(HEX2BIN(C8),"00000000") -> 00000000 | U8: =TEXT(HEX2BIN(D8),"00000000") -> 00000000 | V8: =TEXT(HEX2BIN(E8),"00000000") -> 00000000 | W8: =TEXT(HEX2BIN(F8),"00000000") -> 00000000 | X8: =TEXT(HEX2BIN(G8),"00000000") -> 00000000 | Y8: =TEXT(HEX2BIN(H8),"00000000") -> 00000000 | Z8: =TEXT(HEX2BIN(I8),"00000000") -> 00000000 | ... AH8: =TEXT(HEX2BIN(Q8),"00000000") -> 00000000 | AL8: 0x01 [0] | AM8: SGPIO#0 Control Bit | AN8: 1 | AO8: =MID($C2,2,1) -> 1 | AR8: 2'b01 | AS8: Establishment | AW8: 0x10 [3] | AX8: P0_MEM_VRHOT_N | BA8: =MID($BA4,5,1) -> 1 | BB8: =MID($BB4,5,1) -> 1 | BG8: 0x20 [4] | BH8: RST_BMC_RTCRST | BK8: =MID($BK4,4,1) -> 0 | BL8: =MID($BL4,4,1) -> 0
A9: 70 | B9: =MID($A29,5,2) -> 00 | C9: =MID($A29,8,2) -> 00 | D9: =MID($A29,11,2) -> 00 | E9: =MID($A29,14,2) -> 00 | F9: =MID($A29,17,2) -> 00 | G9: =MID($A29,20,2) -> 00 | H9: =MID($A29,23,2) -> 00 | I9: =MID($A29,26,2) -> 00 | J9: =MID($A29,29,2) -> 00 | K9: =MID($A29,32,2) -> 00 | L9: =MID($A29,35,2) -> 00 | M9: =MID($A29,38,2) -> 00 | N9: =MID($A29,41,2) -> 00 | O9: =MID($A29,44,2) -> 00 | P9: =MID($A29,47,2) -> 00 | Q9: =MID($A29,50,2) -> 00 | S9: =TEXT(HEX2BIN(B9),"00000000") -> 00000000 | T9: =TEXT(HEX2BIN(C9),"00000000") -> 00000000 | U9: =TEXT(HEX2BIN(D9),"00000000") -> 00000000 | V9: =TEXT(HEX2BIN(E9),"00000000") -> 00000000 | W9: =TEXT(HEX2BIN(F9),"00000000") -> 00000000 | X9: =TEXT(HEX2BIN(G9),"00000000") -> 00000000 | Y9: =TEXT(HEX2BIN(H9),"00000000") -> 00000000 | Z9: =TEXT(HEX2BIN(I9),"00000000") -> 00000000 | ... AH9: =TEXT(HEX2BIN(Q9),"00000000") -> 00000000 | AL9: 0x02 [0] | AM9: SGPIO#1 Control Bit | AN9: 1 | AO9: =MID($D2,2,1) -> 1 | AR9: 2'b10 | AS9: Fail | AW9: 0x10 [2] | AX9: FM_CPU0_ERR2_LVT3_N | BA9: =MID($BA4,6,1) -> 1 | BB9: =MID($BB4,6,1) -> 1 | BG9: 0x20 [3] | BH9: FM_REMOTE_DEBUG_EN_N | BK9: =MID($BK4,5,1) -> 0 | BL9: =MID($BL4,5,1) -> 0
A10: 80 | B10: =MID($A30,5,2) -> 00 | C10: =MID($A30,8,2) -> 00 | D10: =MID($A30,11,2) -> 00 | E10: =MID($A30,14,2) -> 00 | F10: =MID($A30,17,2) -> 00 | G10: =MID($A30,20,2) -> 00 | H10: =MID($A30,23,2) -> 00 | I10: =MID($A30,26,2) -> 00 | J10: =MID($A30,29,2) -> 00 | K10: =MID($A30,32,2) -> 00 | L10: =MID($A30,35,2) -> 00 | M10: =MID($A30,38,2) -> 00 | N10: =MID($A30,41,2) -> 00 | O10: =MID($A30,44,2) -> 00 | P10: =MID($A30,47,2) -> 00 | Q10: =MID($A30,50,2) -> 00 | S10: =TEXT(HEX2BIN(B10),"00000000") -> 00000000 | T10: =TEXT(HEX2BIN(C10),"00000000") -> 00000000 | U10: =TEXT(HEX2BIN(D10),"00000000") -> 00000000 | V10: =TEXT(HEX2BIN(E10),"00000000") -> 00000000 | W10: =TEXT(HEX2BIN(F10),"00000000") -> 00000000 | X10: =TEXT(HEX2BIN(G10),"00000000") -> 00000000 | Y10: =TEXT(HEX2BIN(H10),"00000000") -> 00000000 | Z10: =TEXT(HEX2BIN(I10),"00000000") -> 00000000 | ... AH10: =TEXT(HEX2BIN(Q10),"00000000") -> 00000000 | AL10: 0x03 [3:2] | AM10: SGPIO 1 Link Status | AN10: 11 | AO10: =MID($V2,5,2) -> 11 | AP10: =IF(BIN2DEC(AO10)=3,"link stable","!!!!CRC ERROR!!!") -> link stable | AR10: 2'b11 | AS10: Ready | AW10: 0x10 [1] | AX10: FM_CPU0_ERR1_LVT3_N | BA10: =MID($BA4,7,1) -> 1 | BB10: =MID($BB4,7,1) -> 1 | BG10: 0x20 [2] | BH10: FM_SCM_BOARD_REV_ID2 | BK10: =MID($BK4,6,1) -> 1 | BL10: =MID($BL4,6,1) -> 0
A11: 90 | B11: =MID($A31,5,2) -> 00 | C11: =MID($A31,8,2) -> 00 | D11: =MID($A31,11,2) -> 00 | E11: =MID($A31,14,2) -> 00 | F11: =MID($A31,17,2) -> 00 | G11: =MID($A31,20,2) -> 00 | H11: =MID($A31,23,2) -> 00 | I11: =MID($A31,26,2) -> 00 | J11: =MID($A31,29,2) -> 00 | K11: =MID($A31,32,2) -> 00 | L11: =MID($A31,35,2) -> 00 | M11: =MID($A31,38,2) -> 00 | N11: =MID($A31,41,2) -> 00 | O11: =MID($A31,44,2) -> 00 | P11: =MID($A31,47,2) -> 00 | Q11: =MID($A31,50,2) -> 00 | S11: =TEXT(HEX2BIN(B11),"00000000") -> 00000000 | T11: =TEXT(HEX2BIN(C11),"00000000") -> 00000000 | U11: =TEXT(HEX2BIN(D11),"00000000") -> 00000000 | V11: =TEXT(HEX2BIN(E11),"00000000") -> 00000000 | W11: =TEXT(HEX2BIN(F11),"00000000") -> 00000000 | X11: =TEXT(HEX2BIN(G11),"00000000") -> 00000000 | Y11: =TEXT(HEX2BIN(H11),"00000000") -> 00000000 | Z11: =TEXT(HEX2BIN(I11),"00000000") -> 00000000 | ... AH11: =TEXT(HEX2BIN(Q11),"00000000") -> 00000000 | AL11: 0x03 [1:0] | AM11: SGPIO 0 Link Status | AN11: 11 | AO11: =MID($V2,7,2) -> 11 | AP11: =IF(BIN2DEC(AO11)=3,"link stable","!!!!CRC ERROR!!!") -> link stable | AW11: 0x10 [0] | AX11: FM_CPU0_ERR0_LVT3_N | BA11: =MID($BA4,8,1) -> 1 | BB11: =MID($BB4,8,1) -> 1 | BG11: 0x20 [1] | BH11: FM_SCM_BOARD_REV_ID1 | BK11: =MID($BK4,7,1) -> 0 | BL11: =MID($BL4,7,1) -> 1
A12: a0 | B12: =MID($A32,5,2) -> 00 | C12: =MID($A32,8,2) -> 00 | D12: =MID($A32,11,2) -> 00 | E12: =MID($A32,14,2) -> 00 | F12: =MID($A32,17,2) -> 00 | G12: =MID($A32,20,2) -> 00 | H12: =MID($A32,23,2) -> 00 | I12: =MID($A32,26,2) -> 00 | J12: =MID($A32,29,2) -> 00 | K12: =MID($A32,32,2) -> 00 | L12: =MID($A32,35,2) -> 00 | M12: =MID($A32,38,2) -> 00 | N12: =MID($A32,41,2) -> 00 | O12: =MID($A32,44,2) -> 00 | P12: =MID($A32,47,2) -> 00 | Q12: =MID($A32,50,2) -> 00 | S12: =TEXT(HEX2BIN(B12),"00000000") -> 00000000 | T12: =TEXT(HEX2BIN(C12),"00000000") -> 00000000 | U12: =TEXT(HEX2BIN(D12),"00000000") -> 00000000 | V12: =TEXT(HEX2BIN(E12),"00000000") -> 00000000 | W12: =TEXT(HEX2BIN(F12),"00000000") -> 00000000 | X12: =TEXT(HEX2BIN(G12),"00000000") -> 00000000 | Y12: =TEXT(HEX2BIN(H12),"00000000") -> 00000000 | Z12: =TEXT(HEX2BIN(I12),"00000000") -> 00000000 | ... AH12: =TEXT(HEX2BIN(Q12),"00000000") -> 00000000 | AL12: 0x04 [1] | AM12: WOL_OUT | AO12: =MID(W2,7,1) -> 1 | BG12: 0x20 [0] | BH12: FM_SCM_BOARD_REV_ID0 | BK12: =MID($BK4,8,1) -> 0 | BL12: =MID($BL4,8,1) -> 1
A13: b0 | B13: =MID($A33,5,2) -> 00 | C13: =MID($A33,8,2) -> 00 | D13: =MID($A33,11,2) -> 00 | E13: =MID($A33,14,2) -> 00 | F13: =MID($A33,17,2) -> 00 | G13: =MID($A33,20,2) -> 00 | H13: =MID($A33,23,2) -> 00 | I13: =MID($A33,26,2) -> 00 | J13: =MID($A33,29,2) -> 00 | K13: =MID($A33,32,2) -> 00 | L13: =MID($A33,35,2) -> 00 | M13: =MID($A33,38,2) -> 00 | N13: =MID($A33,41,2) -> 00 | O13: =MID($A33,44,2) -> 00 | P13: =MID($A33,47,2) -> 00 | Q13: =MID($A33,50,2) -> 00 | S13: =TEXT(HEX2BIN(B13),"00000000") -> 00000000 | T13: =TEXT(HEX2BIN(C13),"00000000") -> 00000000 | U13: =TEXT(HEX2BIN(D13),"00000000") -> 00000000 | V13: =TEXT(HEX2BIN(E13),"00000000") -> 00000000 | W13: =TEXT(HEX2BIN(F13),"00000000") -> 00000000 | X13: =TEXT(HEX2BIN(G13),"00000000") -> 00000000 | Y13: =TEXT(HEX2BIN(H13),"00000000") -> 00000000 | Z13: =TEXT(HEX2BIN(I13),"00000000") -> 00000000 | ... AH13: =TEXT(HEX2BIN(Q13),"00000000") -> 00000000 | AL13: 0x04 [0] | AM13: WOL_IN | AO13: =MID(W2,8,1) -> 1
A14: c0 | B14: =MID($A34,5,2) -> 00 | C14: =MID($A34,8,2) -> 00 | D14: =MID($A34,11,2) -> 00 | E14: =MID($A34,14,2) -> 00 | F14: =MID($A34,17,2) -> 00 | G14: =MID($A34,20,2) -> 00 | H14: =MID($A34,23,2) -> 00 | I14: =MID($A34,26,2) -> 00 | J14: =MID($A34,29,2) -> 00 | K14: =MID($A34,32,2) -> 00 | L14: =MID($A34,35,2) -> 00 | M14: =MID($A34,38,2) -> 00 | N14: =MID($A34,41,2) -> 00 | O14: =MID($A34,44,2) -> 00 | P14: =MID($A34,47,2) -> 00 | Q14: =MID($A34,50,2) -> 00 | S14: =TEXT(HEX2BIN(B14),"00000000") -> 00000000 | T14: =TEXT(HEX2BIN(C14),"00000000") -> 00000000 | U14: =TEXT(HEX2BIN(D14),"00000000") -> 00000000 | V14: =TEXT(HEX2BIN(E14),"00000000") -> 00000000 | W14: =TEXT(HEX2BIN(F14),"00000000") -> 00000000 | X14: =TEXT(HEX2BIN(G14),"00000000") -> 00000000 | Y14: =TEXT(HEX2BIN(H14),"00000000") -> 00000000 | Z14: =TEXT(HEX2BIN(I14),"00000000") -> 00000000 | ... AH14: =TEXT(HEX2BIN(Q14),"00000000") -> 00000000 | AL14: 0x06 [7:0] | AM14: SGPIO 0 CRC error count | AN14: 00 | AO14: =MID($H2,1,2) -> 00 | AP14: =IF(BIN2DEC(AO14)>0,"!!!!CRC ERROR!!!","link stable") -> link stable
A15: d0 | B15: =MID($A35,5,2) -> 00 | C15: =MID($A35,8,2) -> 00 | D15: =MID($A35,11,2) -> 00 | E15: =MID($A35,14,2) -> 00 | F15: =MID($A35,17,2) -> 00 | G15: =MID($A35,20,2) -> 00 | H15: =MID($A35,23,2) -> 00 | I15: =MID($A35,26,2) -> 00 | J15: =MID($A35,29,2) -> 00 | K15: =MID($A35,32,2) -> 00 | L15: =MID($A35,35,2) -> 00 | M15: =MID($A35,38,2) -> 00 | N15: =MID($A35,41,2) -> 00 | O15: =MID($A35,44,2) -> 00 | P15: =MID($A35,47,2) -> 00 | Q15: =MID($A35,50,2) -> 00 | S15: =TEXT(HEX2BIN(B15),"00000000") -> 00000000 | T15: =TEXT(HEX2BIN(C15),"00000000") -> 00000000 | U15: =TEXT(HEX2BIN(D15),"00000000") -> 00000000 | V15: =TEXT(HEX2BIN(E15),"00000000") -> 00000000 | W15: =TEXT(HEX2BIN(F15),"00000000") -> 00000000 | X15: =TEXT(HEX2BIN(G15),"00000000") -> 00000000 | Y15: =TEXT(HEX2BIN(H15),"00000000") -> 00000000 | Z15: =TEXT(HEX2BIN(I15),"00000000") -> 00000000 | ... AH15: =TEXT(HEX2BIN(Q15),"00000000") -> 00000000 | AL15: 0x07 [7:0] | AM15: SGPIO 1 CRC error count | AN15: 00 | AO15: =MID($I2,1,2) -> 00 | AP15: =IF(BIN2DEC(AO15)>0,"!!!!CRC ERROR!!!","link stable") -> link stable
A16: e0 | B16: =MID($A36,5,2) -> 00 | C16: =MID($A36,8,2) -> 00 | D16: =MID($A36,11,2) -> 00 | E16: =MID($A36,14,2) -> 00 | F16: =MID($A36,17,2) -> 00 | G16: =MID($A36,20,2) -> 00 | H16: =MID($A36,23,2) -> 00 | I16: =MID($A36,26,2) -> 00 | J16: =MID($A36,29,2) -> 00 | K16: =MID($A36,32,2) -> 00 | L16: =MID($A36,35,2) -> 00 | M16: =MID($A36,38,2) -> 00 | N16: =MID($A36,41,2) -> 00 | O16: =MID($A36,44,2) -> 00 | P16: =MID($A36,47,2) -> 00 | Q16: =MID($A36,50,2) -> 00 | S16: =TEXT(HEX2BIN(B16),"00000000") -> 00000000 | T16: =TEXT(HEX2BIN(C16),"00000000") -> 00000000 | U16: =TEXT(HEX2BIN(D16),"00000000") -> 00000000 | V16: =TEXT(HEX2BIN(E16),"00000000") -> 00000000 | W16: =TEXT(HEX2BIN(F16),"00000000") -> 00000000 | X16: =TEXT(HEX2BIN(G16),"00000000") -> 00000000 | Y16: =TEXT(HEX2BIN(H16),"00000000") -> 00000000 | Z16: =TEXT(HEX2BIN(I16),"00000000") -> 00000000 | ... AH16: =TEXT(HEX2BIN(Q16),"00000000") -> 00000000 | AL16: 0x08 [7:0] | AM16: SGPIO 0 CRC good count | AN16: 17 | AO16: =MID($J2,1,2) -> 86 | AR16: (0x0A)Power on | AX16: Common info | BA16: EXP. | BB16: Data.
A17: f0 | B17: =MID($A37,5,2) -> 00 | C17: =MID($A37,8,2) -> 03 | D17: =MID($A37,11,2) -> 06 | E17: =MID($A37,14,2) -> 00 | F17: =MID($A37,17,2) -> 07 | G17: =MID($A37,20,2) -> 18 | H17: =MID($A37,23,2) -> 25 | I17: =MID($A37,26,2) -> 00 | J17: =MID($A37,29,2) -> 00 | K17: =MID($A37,32,2) -> 00 | L17: =MID($A37,35,2) -> 00 | M17: =MID($A37,38,2) -> 00 | N17: =MID($A37,41,2) -> 00 | O17: =MID($A37,44,2) -> 00 | P17: =MID($A37,47,2) -> 00 | Q17: =MID($A37,50,2) -> 00 | S17: =TEXT(HEX2BIN(B17),"00000000") -> 00000000 | T17: =TEXT(HEX2BIN(C17),"00000000") -> 00000011 | U17: =TEXT(HEX2BIN(D17),"00000000") -> 00000110 | V17: =TEXT(HEX2BIN(E17),"00000000") -> 00000000 | W17: =TEXT(HEX2BIN(F17),"00000000") -> 00000111 | X17: =TEXT(HEX2BIN(G17),"00000000") -> 00011000 | Y17: =TEXT(HEX2BIN(H17),"00000000") -> 00100101 | Z17: =TEXT(HEX2BIN(I17),"00000000") -> 00000000 | ... AH17: =TEXT(HEX2BIN(Q17),"00000000") -> 00000000 | AL17: 0x09 [7:0] | AM17: SGPIO 1 CRC good count | AN17: 14 | AO17: =MID($K2,1,2) -> cd | AR17: 0x0 | AS17: All power rails are disabled | AW17: 0x11 [7:0] | AX17: Check SGPIO 0 Data | BA17: =AN26 -> 10111110 | BB17: =AO26 -> 10111110 | BH17: Common info | BK17: EXP. | BL17: Data.
AM18: Power Status | AR18: 0x1 | AS18: P3V3_BMC_STBY is ready | AW18: 0x11 [7] | AX18: P1_MEM_VRHOT_N | BA18: =MID($BA17,1,1) -> 1 | BB18: =MID($BB17,1,1) -> 1 | BG18: 0x21 [7:0] | BH18: Check SGPIO 0 Data | BK18: =AN37 -> 01001100 | BL18: =AO37 -> 01001100
AL19: 0x0A [7:0] | AM19: DC-SCM VR on/off status Register | AN19: 09 | AO19: =MID($L2,1,2) -> 09 | AR19: 0x2 | AS19: All of the above and P2V5_BMC_STBY is enabled. | AW19: 0x11 [5] | AX19: PDB_ALERT2_N | BA19: =MID($BA17,3,1) -> 1 | BB19: =MID($BB17,3,1) -> 1 | BG19: 0x21 [7] | BH19: FM_JTAG_TCK_MUX_SEL | BK19: =MID($BK18,1,1) -> 0 | BL19: =MID($BL18,1,1) -> 0
A20: Paste LOG Here ( i2cdump -y -a -f 15 0x60 ) | AL20: 0x0B [7:0] | AM20: Power Good Status Register | AN20: 11111111 | AO20: =MID($AD2,1,8) -> 11111111 | AR20: 0x3 | AS20: All of the above and P1V8_BMC_STBY is enabled. | AW20: 0x11 [4] | AX20: PDB_ALERT1_N | BA20: =MID($BA17,4,1) -> 1 | BB20: =MID($BB17,4,1) -> 1 | BG20: 0x21 [6] | BH20: FM_UV_ADR_TRIGGER_EN | BK20: =MID($BK18,2,1) -> 1 | BL20: =MID($BL18,2,1) -> 1
A21: 0 1 2 3 4 5 6 7 8 9 a b c d e f 0123456789abcdef | AM21: Board Revision / BMC Scratch Pad | AR21: 0x4 | AS21: All of the above and P1V2_BMC_STBY is enabled. | AW21: 0x11 [3] | AX21: PWRGD_CPU0_LVC3 | BA21: =MID($BA17,5,1) -> 1 | BB21: =MID($BB17,5,1) -> 1 | BG21: 0x21 [5] | BH21: FM_UART2_FPGA_SELECT | BK21: =MID($BK18,3,1) -> 0 | BL21: =MID($BL18,3,1) -> 0
A22: 00: 36 01 01 0f 03 00 00 00 86 cd 09 ff 1b 00 00 00 6????...???.?... | AE22: Common info | AH22: EXP. | AI22: Data. | AL22: 0x0C [5:3] | AM22: SCM Board Revision ID | AN22: 100 | AO22: =MID($AE2,3,3) -> 011 | AP22: =IF(AO22="000", "POC", IF(AO22="001", "EVT", IF(AO22="010", "DVT", IF(AO22="011", "PVT", IF(AO22="100", "MP", "Unknown"))))) -> PVT | AR22: 0x5 | AS22: All of the above and P1V8_LION is enabled. | AW22: 0x11 [2] | AX22: IRQ_PVCCIN_CPU0_VRHOT_LVC3_N | BA22: =MID($BA17,6,1) -> 1 | BB22: =MID($BB17,6,1) -> 1 | BG22: 0x21 [4] | BH22: FM_USB_CPU_FPGA_SELECT | BK22: =MID($BK18,4,1) -> 0 | BL22: =MID($BL18,4,1) -> 0
A23: 10: bf be eb f8 ff ff ff f7 9f 0f 00 00 00 00 00 00 ????...???...... | AD23: 0x0B [7:0] | AE23: Power Good Status | AH23: =AN20 -> 11111111 | AI23: =AO20 -> 11111111 | AL23: 0x0C [2:0] | AM23: HPM Board Revision ID | AN23: 011 | AO23: =MID($AE2,6,3) -> 011 | AP23: =IF(AO23="000", "POC", IF(AO23="001", "EVT", IF(AO23="010", "DVT", IF(AO23="011", "PVT", IF(AO23="100", "MP", "Unknown"))))) -> PVT | AR23: 0x6 | AS23: All of the above and P1V0_BMC_STBY is enabled. | AW23: 0x11 [1] | AX23: FM_CPU0_THERMTRIP_LATCH_LVT3_N | BA23: =MID($BA17,7,1) -> 1 | BB23: =MID($BB17,7,1) -> 1 | BG23: 0x21 [3] | BH23: PSU2_ALERT_EN_N | BK23: =MID($BK18,5,1) -> 1 | BL23: =MID($BL18,5,1) -> 1
A24: 20: 63 4c de ce 7f 0d 00 00 fe 1f 00 00 00 00 00 00 cL????..??...... | AD24: 0x0B [7] | AE24: HPM_STBY_RDY | AH24: =MID($AH23,1,1) -> 1 | AI24: =MID($AI23,1,1) -> 1 | AM24: SGPIO#0 Input Data | AR24: 0x7 | AS24: All of the above and P1V07_BMC_STBY is enabled. | AW24: 0x11 [0] | AX24: P0_SKTOCC_N | BA24: =MID($BA17,8,1) -> 0 | BB24: =MID($BB17,8,1) -> 0 | BG24: 0x21 [2] | BH24: PSU_ALERT_PLD_EN_N | BK24: =MID($BK18,6,1) -> 1 | BL24: =MID($BL18,6,1) -> 1
A25: 30: 00 00 f9 0b 00 00 00 00 00 00 00 00 00 00 00 00 ..??............ | AD25: 0x0B [6] | AE25: P1V07_BMC_STBY | AH25: =MID($AH23,2,1) -> 1 | AI25: =MID($AI23,2,1) -> 1 | AL25: 0x10 [7:0] | AM25: Check SGPIO 0 Data | AN25: 10111111 | AO25: =MID($S3,1,8) -> 10111111 | AR25: 0x9 | AS25: Power ON (All of the above and HPM_STBY_RDY is ready). | BG25: 0x21 [1] | BH25: PDB_ALERT1_EN_N | BK25: =MID($BK18,7,1) -> 0 | BL25: =MID($BL18,7,1) -> 0
A26: 40: 10 00 00 00 00 00 00 00 00 00 00 00 00 00 00 00 ?............... | AD26: 0x0B [5] | AE26: P1V0_BMC_STBY | AH26: =MID($AH23,3,1) -> 1 | AI26: =MID($AI23,3,1) -> 1 | AL26: 0x11 [7:0] | AM26: Check SGPIO 0 Data | AN26: 10111110 | AO26: =MID($T3,1,8) -> 10111110 | BG26: 0x21 [0] | BH26: FM_TPM_MOD_PRES_N | BK26: =MID($BK18,8,1) -> 0 | BL26: =MID($BL18,8,1) -> 0
A27: 50: 00 00 00 00 00 00 00 00 00 00 00 00 00 00 00 00 ................ | AD27: 0x0B [4] | AE27: P0V8_LION_CORE | AH27: =MID($AH23,4,1) -> 1 | AI27: =MID($AI23,4,1) -> 1 | AL27: 0x12 [7:0] | AM27: Check SGPIO 0 Data | AN27: 11101011 | AO27: =MID($U3,1,8) -> 11101011 | AR27: (0x0A) Power off
A28: 60: 00 00 00 00 00 00 00 00 00 00 00 00 00 00 00 00 ................ | AD28: 0x0B [3] | AE28: P1V2_BMC_STBY | AH28: =MID($AH23,5,1) -> 1 | AI28: =MID($AI23,5,1) -> 1 | AL28: 0x13 [7:0] | AM28: Check SGPIO 0 Data | AN28: 11111000 | AO28: =MID($V3,1,8) -> 11111000 | AR28: 0xA | AS28: P1V07_BMC_STBY_OFF
A29: 70: 00 00 00 00 00 00 00 00 00 00 00 00 00 00 00 00 ................ | AD29: 0x0B [2] | AE29: P1V8_BMC_STBY | AH29: =MID($AH23,6,1) -> 1 | AI29: =MID($AI23,6,1) -> 1 | AL29: 0x14 [7:0] | AM29: Check SGPIO 0 Data | AN29: 11111111 | AO29: =MID($W3,1,8) -> 11111111 | AR29: 0xB | AS29: P1V0_BMC_STBY_OFF | AX29: Common info | BA29: EXP. | BB29: Data.
A30: 80: 00 00 00 00 00 00 00 00 00 00 00 00 00 00 00 00 ................ | AD30: 0x0B [1] | AE30: P2V5_BMC_STBY | AH30: =MID($AH23,7,1) -> 1 | AI30: =MID($AI23,7,1) -> 1 | AL30: 0x15 [7:0] | AM30: Check SGPIO 0 Data | AN30: 11111111 | AO30: =MID($X3,1,8) -> 11111111 | AR30: 0xC | AS30: P1V8_LION_OFF | AW30: 0x12 [7:0] | AX30: Check SGPIO 0 Data | BA30: =AN27 -> 11101011 | BB30: =AO27 -> 11101011
A31: 90: 00 00 00 00 00 00 00 00 00 00 00 00 00 00 00 00 ................ | AD31: 0x0B [0] | AE31: P3V3_STBY_SCM | AH31: =MID($AH23,8,1) -> 1 | AI31: =MID($AI23,8,1) -> 1 | AL31: 0x16 [7:0] | AM31: Check SGPIO 0 Data | AN31: 11111111 | AO31: =MID($Y3,1,8) -> 11111111 | AR31: 0xD | AS31: P1V2_BMC_STBY_OFF | AW31: 0x12 [7] | AX31: PWRGD_CPU1_LVC3 | BA31: =MID($BA30,1,1) -> 1 | BB31: =MID($BB30,1,1) -> 1 | BH31: Common info | BK31: EXP. | BL31: Data.
A32: a0: 00 00 00 00 00 00 00 00 00 00 00 00 00 00 00 00 ................ | AL32: 0x17 [7:0] | AM32: Check SGPIO 0 Data | AN32: 10110111 | AO32: =MID($Z3,1,8) -> 11110111 | AR32: 0xE | AS32: P2V5_BMC_STBY_OFF | AW32: 0x12 [6] | AX32: IRQ_PVCCIN_CPU1_VRHOT_LVC3_N | BA32: =MID($BA30,2,1) -> 1 | BB32: =MID($BB30,2,1) -> 1 | BG32: 0x22 [7:0] | BH32: Check SGPIO 0 Data | BK32: =AN38 -> 11011110 | BL32: =AO38 -> 11011110
A33: b0: 00 00 00 00 00 00 00 00 00 00 00 00 00 00 00 00 ................ | AL33: 0x18 [7:0] | AM33: Check SGPIO 0 Data | AN33: 10011111 | AO33: =MID($AA3,1,8) -> 10011111 | AR33: 0xF | AS33: P1V8_BMC_STBY_OFF | AW33: 0x12 [5] | AX33: FM_CPU1_THERMTRIP_LATCH_LVT3_N | BA33: =MID($BA30,3,1) -> 1 | BB33: =MID($BB30,3,1) -> 1 | BG33: 0x22 [7] | BH33: SMB_SLIVER_RST_BMC_N | BK33: =MID($BK32,1,1) -> 1 | BL33: =MID($BL32,1,1) -> 1
A34: c0: 00 00 00 00 00 00 00 00 00 00 00 00 00 00 00 00 ................ | AL34: 0x19 [3:0] | AM34: Check SGPIO 0 Data | AN34: 1111 | AO34: =MID($AB3,5,8) -> 1111 | AR34: 0x10 | AS34: POWER_FAULT (Any power rail abruptly drops after power on) | AW34: 0x12 [4] | AX34: P1_SKTOCC_N | BA34: =MID($BA30,4,1) -> 0 | BB34: =MID($BB30,4,1) -> 0 | BG34: 0x22 [6] | BH34: USB_EX1_CPLD_OC_N | BK34: =MID($BK32,2,1) -> 1 | BL34: =MID($BL32,2,1) -> 1
A35: d0: 00 00 00 00 00 00 00 00 00 00 00 00 00 00 00 00 ................ | AM35: SGPIO#0 OutputData | AW35: 0x12 [3] | AX35: P1_PROCHOT_N | BA35: =MID($BA30,5,1) -> 1 | BB35: =MID($BB30,5,1) -> 1 | BG35: 0x22 [5] | BH35: FM_BIOS_RECOVERY | BK35: =MID($BK32,3,1) -> 0 | BL35: =MID($BL32,3,1) -> 0
A36: e0: 00 00 00 00 00 00 00 00 00 00 00 00 00 00 00 00 ................ | AL36: 0x20 [7:0] | AM36: Check SGPIO 0 Data | AN36: 01100100 | AO36: =MID($S4,1,8) -> 01100011 | AW36: 0x12 [1] | AX36: P1_BMC_MEMTRIP_N | BA36: =MID($BA30,7,1) -> 1 | BB36: =MID($BB30,7,1) -> 1 | BG36: 0x22 [4] | BH36: IRQ_BMC_CPU_NMI_R | BK36: =MID($BK32,4,1) -> 1 | BL36: =MID($BL32,4,1) -> 1
A37: f0: 00 03 06 00 07 18 25 00 00 00 00 00 00 00 00 00 .??.??%......... | AL37: 0x21 [7:0] | AM37: Check SGPIO 0 Data | AN37: 01001100 | AO37: =MID($T4,1,8) -> 01001100 | AW37: 0x12 [0] | AX37: H_CPU1_MEMHOT_OUT_LVC1_N | BA37: =MID($BA30,8,1) -> 1 | BB37: =MID($BB30,8,1) -> 1 | BG37: 0x22 [3] | BH37: FM_ADR_ACK | BK37: =MID($BK32,5,1) -> 1 | BL37: =MID($BL32,5,1) -> 1
AL38: 0x22 [7:0] | AM38: Check SGPIO 0 Data | AN38: 11011110 | AO38: =MID($U4,1,8) -> 11011110 | BG38: 0x22 [2] | BH38: FM_ME_RECOVERY_N | BK38: =MID($BK32,6,1) -> 1 | BL38: =MID($BL32,6,1) -> 1
AL39: 0x23 [7:0] | AM39: Check SGPIO 0 Data | AN39: 11001110 | AO39: =MID($V4,1,8) -> 11001110 | AR39: Board Revision | BG39: 0x22 [1] | BH39: BMC_RSTBTN_OUT_N | BK39: =MID($BK32,7,1) -> 1 | BL39: =MID($BL32,7,1) -> 1
AL40: 0x24 [7:0] | AM40: Check SGPIO 0 Data | AN40: 01101111 | AO40: =MID($W4,1,8) -> 01111111 | AR40: 3'b000 | AS40: POC | BG40: 0x22 [0] | BH40: FM_SPD_SWITCH_CTRL_N | BK40: =MID($BK32,8,1) -> 0 | BL40: =MID($BL32,8,1) -> 0
...

Sheet CPLD1 reg
A1: LOG | B1: 0 | C1: 1 | D1: 2 | E1: 3 | F1: 4 | G1: 5 | H1: 6 | I1: 7 | J1: 8 | K1: 9 | L1: A | M1: B | N1: C | O1: D | P1: E | Q1: F | S1: 0 | T1: 1 | U1: 2 | V1: 3 | W1: 4 | X1: 5 | Y1: 6 | Z1: 7 | AA1: 8 | AB1: 9 | AC1: A | AD1: B | AE1: C | AF1: D | AG1: E | AH1: F
A2: 0 | B2: =MID($A22,5,2) -> 00 | C2: =MID($A22,8,2) -> 00 | D2: =MID($A22,11,2) -> c3 | E2: =MID($A22,14,2) -> 0c | F2: =MID($A22,17,2) -> 03 | G2: =MID($A22,20,2) -> 80 | H2: =MID($A22,23,2) -> 00 | I2: =MID($A22,26,2) -> 03 | J2: =MID($A22,29,2) -> 00 | K2: =MID($A22,32,2) -> ff | L2: =MID($A22,35,2) -> fe | M2: =MID($A22,38,2) -> 00 | N2: =MID($A22,41,2) -> 00 | O2: =MID($A22,44,2) -> fc | P2: =MID($A22,47,2) -> 00 | Q2: =MID($A22,50,2) -> 00 | S2: =TEXT(HEX2BIN(B2),"00000000") -> 00000000 | T2: =TEXT(HEX2BIN(C2),"00000000") -> 00000000 | U2: =TEXT(HEX2BIN(D2),"00000000") -> 11000011 | V2: =TEXT(HEX2BIN(E2),"00000000") -> 00001100 | W2: =TEXT(HEX2BIN(F2),"00000000") -> 00000011 | X2: =TEXT(HEX2BIN(G2),"00000000") -> 10000000 | Y2: =TEXT(HEX2BIN(H2),"00000000") -> 00000000 | Z2: =TEXT(HEX2BIN(I2),"00000000") -> 00000011 | ... AH2: =TEXT(HEX2BIN(Q2),"00000000") -> 00000000
